Workbook

Sheet Executive_Summary
A1: Chile Regional Tourism Competitiveness: Decision Dashboard
A2: 15-region legacy analytical frame | Prepared from DB1–DB5| v2: identities for Metropolitana, Aysén and Magallanes revised (see Identity_Scoring)
A4: Code | B4: Region | C4: Priority Tier | D4: Primary Identity | E4: Secondary Identity | F4: Traveler Segment | G4: Historical Composite | H4: Asset Score | I4: Enabler Score | J4: Recent Demand | K4: Digital Readiness | L4: Priority Score | M4: Latest Occupancy % | N4: Intl Recovery %
A5: XV | B5: Arica y Parinacota | C5: Wait | D5: Community & Indigenous | E5: Culture & Heritage | F5: responsible cultural and community-based travelers; culture-led city-break and heritage travelers | G5: 29.215553 | H5: 27.938624 | I5: 29.534786 | J5: 36.264197 | K5: 28.834379 | L5: =0.5*G5+0.3*J5+0.2*K5 -> 31.253912 | M5: 57 | N5: 138.39133
A6: I | B6: Tarapacá | C6: Wait | D6: Wellness & Thermal | E6: Astro & Desert | F6: wellness, thermal and regional leisure travelers; experience-seeking, astronomy and photography travelers | G6: 26.625575 | H6: 21.418694 | I6: 27.927295 | J6: 39.520943 | K6: 34.144353 | L6: =0.5*G6+0.3*J6+0.2*K6 -> 31.997941 | M6: 57.15 | N6: 148.02766
A7: II | B7: Antofagasta | C7: Prepare First | D7: Astro & Desert | E7: Culture & Heritage | F7: experience-seeking, astronomy and photography travelers; culture-led city-break and heritage travelers | G7: 36.163446 | H7: 32.600886 | I7: 37.054085 | J7: 35.384703 | K7: 50.625421 | L7: =0.5*G7+0.3*J7+0.2*K7 -> 38.822218 | M7: 54.2 | N7: 126.89083
A8: III | B8: Atacama | C8: Prepare First | D8: Astro & Desert | E8: Coastal & Cruise | F8: experience-seeking, astronomy and photography travelers; coastal leisure, cruise and family travelers | G8: 26.283286 | H8: 21.979582 | I8: 27.359212 | J8: 41.227633 | K8: 29.863337 | L8: =0.5*G8+0.3*J8+0.2*K8 -> 31.482601 | M8: 57.35 | N8: 138.212
A9: IV | B9: Coquimbo | C9: Scale Now | D9: Coastal & Cruise | E9: Astro & Desert | F9: coastal leisure, cruise and family travelers; experience-seeking, astronomy and photography travelers | G9: 34.386152 | H9: 29.848072 | I9: 35.520672 | J9: 62.310224 | K9: 57.674328 | L9: =0.5*G9+0.3*J9+0.2*K9 -> 47.421009 | M9: 61.475 | N9: 158.34572
A10: V | B10: Valparaíso | C10: Scale Now | D10: Coastal & Cruise | E10: Culture & Heritage | F10: coastal leisure, cruise and family travelers; culture-led city-break and heritage travelers | G10: 42.497286 | H10: 46.007667 | I10: 41.619691 | J10: 70.904002 | K10: 68.955855 | L10: =0.5*G10+0.3*J10+0.2*K10 -> 56.311015 | M10: 64.325 | N10: 128.76497
A11: RM | B11: Metropolitana | C11: Scale Now | D11: Culture & Heritage | E11: Winter & Mountain | F11: culture-led city-break and heritage travelers; winter-sports and mountain-adventure travelers | G11: 51.027407 | H11: 34.494686 | I11: 55.160587 | J11: 95.230769 | K11: 97.883598 | L11: =0.5*G11+0.3*J11+0.2*K11 -> 73.659654 | M11: 62 | N11: 174.71414
A12: VI | B12: O'Higgins | C12: Prepare First | D12: Wine & Gastronomy | E12: Culture & Heritage | F12: affluent culinary and wine travelers; culture-led city-break and heritage travelers | G12: 27.690385 | H12: 29.737326 | I12: 27.17865 | J12: 30.399641 | K12: 18.715728 | L12: =0.5*G12+0.3*J12+0.2*K12 -> 26.70823 | M12: 58.25 | N12: 122.28954
A13: VII | B13: Maule | C13: Prepare First | D13: Wellness & Thermal | E13: Winter & Mountain | F13: wellness, thermal and regional leisure travelers; winter-sports and mountain-adventure travelers | G13: 28.117204 | H13: 28.723329 | I13: 27.965673 | J13: 59.352236 | K13: 77.15703 | L13: =0.5*G13+0.3*J13+0.2*K13 -> 47.295679 | M13: 62.75 | N13: 157.65687
A14: VIII | B14: Biobío | C14: Prepare First | D14: Culture & Heritage | E14: Winter & Mountain | F14: culture-led city-break and heritage travelers; winter-sports and mountain-adventure travelers | G14: 36.846173 | H14: 26.559771 | I14: 39.417774 | J14: 45.638541 | K14: 52.766353 | L14: =0.5*G14+0.3*J14+0.2*K14 -> 42.667919 | M14: 54.35 | N14: 150.95831
A15: IX | B15: Araucanía | C15: Prepare First | D15: Wellness & Thermal | E15: Winter & Mountain | F15: wellness, thermal and regional leisure travelers; winter-sports and mountain-adventure travelers | G15: 33.592731 | H15: 42.672929 | I15: 31.322682 | J15: 35.709395 | K15: 10.423953 | L15: =0.5*G15+0.3*J15+0.2*K15 -> 29.593975 | M15: 49.7 | N15: 143.23172
A16: XIV | B16: Los Ríos | C16: Prepare First | D16: Wellness & Thermal | E16: Nature & Adventure | F16: wellness, thermal and regional leisure travelers; eco-conscious adventure and longer-stay travelers | G16: 26.843005 | H16: 23.562633 | I16: 27.663098 | J16: 29.82618 | K16: 16.3681 | L16: =0.5*G16+0.3*J16+0.2*K16 -> 25.642977 | M16: 53.775 | N16: 133.10416
... A19: XII | B19: Magallanes y Antártica | C19: Scale Now | D19: Nature & Adventure | E19: Coastal & Cruise | F19: eco-conscious adventure and longer-stay travelers; expedition-cruise and Antarctic-gateway travelers | G19: 39.490988 | H19: 32.16918 | I19: 41.32144 | J19: 35.089993 | K19: 57.032018 | L19: =0.5*G19+0.3*J19+0.2*K19 -> 41.678896 | M19: 55.775 | N19: 135.49344

Sheet Regional_Profiles
A1: Regional Positioning and Action Logic
A2: v2: yellow cells mark revised identities (Metropolitana, Aysén, Magallanes). Rationale and data ranks in Identity_Scoring.
A3: Code | B3: Region | C3: Tier | D3: Identity 1 | E3: Identity 2 | F3: Target Traveler | G3: Top Dimensional Strengths | H3: Main Dimensional Gaps | I3: Priority Score | J3: Latest 4Q Arrivals | K3: Latest Occupancy % | L3: Latest ADR USD | M3: Recommended Action
A4: XV | B4: Arica y Parinacota | C4: Wait | D4: Community & Indigenous | E4: Culture & Heritage | F4: responsible cultural and community-based travelers; culture-led city-break and heritage travelers | G4: D8 52, D7 50 | H4: D10 6, D6 17 | I4: 31.253912 | J4: 89450 | K4: 57 | L4: 120.4725 | M4: Do not prioritize near-term promotion; validate product-market fit and close governance/service gaps first.
A5: I | B5: Tarapacá | C5: Wait | D5: Wellness & Thermal | E5: Astro & Desert | F5: wellness, thermal and regional leisure travelers; experience-seeking, astronomy and photography travelers | G5: D7 49, D8 40 | H5: D9 12, D1 15 | I5: 31.997941 | J5: 86385 | K5: 57.15 | L5: 117.5975 | M5: Do not prioritize near-term promotion; validate product-market fit and close governance/service gaps first.
A6: II | B6: Antofagasta | C6: Prepare First | D6: Astro & Desert | E6: Culture & Heritage | F6: experience-seeking, astronomy and photography travelers; culture-led city-break and heritage travelers | G6: D8 66, D7 50 | H6: D10 22, D1 24 | I6: 38.822218 | J6: 139385 | K6: 54.2 | L6: 121.5225 | M6: Fund foundational workforce, service, mobility, digital or safety gaps before broad promotion.
A7: III | B7: Atacama | C7: Prepare First | D7: Astro & Desert | E7: Coastal & Cruise | F7: experience-seeking, astronomy and photography travelers; coastal leisure, cruise and family travelers | G7: D7 53, D8 46 | H7: D1 10, D5 15 | I7: 31.482601 | J7: 110003 | K7: 57.35 | L7: 121.285 | M7: Fund foundational workforce, service, mobility, digital or safety gaps before broad promotion.
A8: IV | B8: Coquimbo | C8: Scale Now | D8: Coastal & Cruise | E8: Astro & Desert | F8: coastal leisure, cruise and family travelers; experience-seeking, astronomy and photography travelers | G8: D7 59, D10 51 | H8: D6 15, D5 18 | I8: 47.421009 | J8: 139401 | K8: 61.475 | L8: 132.575 | M8: Scale promotion and investment now, but pair growth with capacity and sustainability safeguards.
A9: V | B9: Valparaíso | C9: Scale Now | D9: Coastal & Cruise | E9: Culture & Heritage | F9: coastal leisure, cruise and family travelers; culture-led city-break and heritage travelers | G9: D7 60, D8 53 | H9: D9 30, D10 33 | I9: 56.311015 | J9: 273183 | K9: 64.325 | L9: 135.7025 | M9: Scale promotion and investment now, but pair growth with capacity and sustainability safeguards.
A10: RM | B10: Metropolitana | C10: Scale Now | D10: Culture & Heritage | E10: Winter & Mountain | F10: culture-led city-break and heritage travelers; winter-sports and mountain-adventure travelers | G10: D3 62, D4 62 | H10: D2 17, D9 33 | I10: 73.659654 | J10: 475650 | K10: 62 | L10: 177.9475 | M10: Scale promotion and investment now, but pair growth with capacity and sustainability safeguards.
A11: VI | B11: O'Higgins | C11: Prepare First | D11: Wine & Gastronomy | E11: Culture & Heritage | F11: affluent culinary and wine travelers; culture-led city-break and heritage travelers | G11: D7 64, D8 55 | H11: D5 8, D4 12 | I11: 26.70823 | J11: 80165 | K11: 58.25 | L11: 105.1225 | M11: Fund foundational workforce, service, mobility, digital or safety gaps before broad promotion.
A12: VII | B12: Maule | C12: Prepare First | D12: Wellness & Thermal | E12: Winter & Mountain | F12: wellness, thermal and regional leisure travelers; winter-sports and mountain-adventure travelers | G12: D7 61, D8 50 | H12: D4 13, D3 15 | I12: 47.295679 | J12: 108066 | K12: 62.75 | L12: 159.355 | M12: Fund foundational workforce, service, mobility, digital or safety gaps before broad promotion.
A13: VIII | B13: Biobío | C13: Prepare First | D13: Culture & Heritage | E13: Winter & Mountain | F13: culture-led city-break and heritage travelers; winter-sports and mountain-adventure travelers | G13: D10 80, D7 66 | H13: D4 17, D6 20 | I13: 42.667919 | J13: 144588 | K13: 54.35 | L13: 128.78 | M13: Fund foundational workforce, service, mobility, digital or safety gaps before broad promotion.
A14: IX | B14: Araucanía | C14: Prepare First | D14: Wellness & Thermal | E14: Winter & Mountain | F14: wellness, thermal and regional leisure travelers; winter-sports and mountain-adventure travelers | G14: D7 60, D2 56 | H14: D9 13, D3 21 | I14: 29.593975 | J14: 163446 | K14: 49.7 | L14: 109.0175 | M14: Fund foundational workforce, service, mobility, digital or safety gaps before broad promotion.
A15: XIV | B15: Los Ríos | C15: Prepare First | D15: Wellness & Thermal | E15: Nature & Adventure | F15: wellness, thermal and regional leisure travelers; eco-conscious adventure and longer-stay travelers | G15: D7 65, D8 49 | H15: D1 10, D5 12 | I15: 25.642977 | J15: 99374 | K15: 53.775 | L15: 113.37 | M15: Fund foundational workforce, service, mobility, digital or safety gaps before broad promotion.
... A18: XII | B18: Magallanes y Antártica | C18: Scale Now | D18: Nature & Adventure | E18: Coastal & Cruise | F18: eco-conscious adventure and longer-stay travelers; expedition-cruise and Antarctic-gateway travelers | G18: D7 66, D8 53 | H18: D10 10, D1 13 | I18: 41.678896 | J18: 100571 | K18: 55.775 | L18: 197.9675 | M18: Scale promotion and investment now, but pair growth with capacity and sustainability safeguards.

Sheet Dimension_Scores
A1: Normalized Dimension Scores (0-100)
A3: Code | B3: Region | C3: D1 | D3: D2 | E3: D3 | F3: D4 | G3: D5 | H3: D6 | I3: D7 | J3: D8 | K3: D9 | L3: D10 | M3: Overall | N3: Asset (D1–D2) | O3: Enabler (D3–D10) | P3: Tier | R3: D1 | S3: Cultural Heritage & Events
A4: XV | B4: Arica y Parinacota | C4: 22.283865 | D4: 33.593383 | E4: 32.395896 | F4: 25.927985 | G4: 28.553771 | H4: 17.363602 | I4: 50.22718 | J4: 51.94078 | K4: 23.896516 | L4: 5.9725558 | M4: =AVERAGE(C4:L4) -> 29.215553 | N4: =AVERAGE(C4:D4) -> 27.938624 | O4: =AVERAGE(E4:L4) -> 29.534786 | P4: Wait | R4: D2 | S4: Natural Resources & Sustainability
A5: I | B5: Tarapacá | C5: 15.145645 | D5: 27.691743 | E5: 30.134838 | F5: 29.378623 | G5: 24.008176 | H5: 21.227666 | I5: 49.05692 | J5: 39.837634 | K5: 12.154815 | L5: 17.61969 | M5: =AVERAGE(C5:L5) -> 26.625575 | N5: =AVERAGE(C5:D5) -> 21.418694 | O5: =AVERAGE(E5:L5) -> 27.927295 | P5: Wait | R5: D3 | S5: Human Resources & Workforce
A6: II | B6: Antofagasta | C6: 23.78597 | D6: 41.415802 | E6: 28.045293 | F6: 28.104243 | G6: 33.120996 | H6: 31.326621 | I6: 50.147795 | J6: 66.281922 | K6: 37.550834 | L6: 21.854979 | M6: =AVERAGE(C6:L6) -> 36.163446 | N6: =AVERAGE(C6:D6) -> 32.600886 | O6: =AVERAGE(E6:L6) -> 37.054085 | P6: Prepare First | R6: D4 | S6: Tourism Infrastructure
A7: III | B7: Atacama | C7: 9.5479185 | D7: 34.411246 | E7: 22.018434 | F7: 19.567644 | G7: 14.693321 | H7: 23.134549 | I7: 53.191973 | J7: 46.438893 | K7: 21.54423 | L7: 18.284654 | M7: =AVERAGE(C7:L7) -> 26.283286 | N7: =AVERAGE(C7:D7) -> 21.979582 | O7: =AVERAGE(E7:L7) -> 27.359212 | P7: Prepare First | R7: D5 | S7: Mobility & Transportation
A8: IV | B8: Coquimbo | C8: 19.62268 | D8: 40.073464 | E8: 25.401077 | F8: 42.140811 | G8: 18.002593 | H8: 15.471814 | I8: 59.20911 | J8: 46.334826 | K8: 26.447633 | L8: 51.157512 | M8: =AVERAGE(C8:L8) -> 34.386152 | N8: =AVERAGE(C8:D8) -> 29.848072 | O8: =AVERAGE(E8:L8) -> 35.520672 | P8: Scale Now | R8: D6 | S8: Tourism-Related Services
A9: V | B9: Valparaíso | C9: 49.152672 | D9: 42.862662 | E9: 35.132094 | F9: 44.698128 | G9: 34.921937 | H9: 43.075146 | I9: 59.759528 | J9: 52.722766 | K9: 29.696202 | L9: 32.951729 | M9: =AVERAGE(C9:L9) -> 42.497286 | N9: =AVERAGE(C9:D9) -> 46.007667 | O9: =AVERAGE(E9:L9) -> 41.619691 | P9: Scale Now | R9: D7 | S9: Security & Safety
A10: RM | B10: Metropolitana | C10: 52.04743 | D10: 16.941943 | E10: 61.707192 | F10: 61.701864 | G10: 57.908505 | H10: 54.879212 | I10: 56.901021 | J10: 54.099651 | K10: 33.333333 | L10: 60.753915 | M10: =AVERAGE(C10:L10) -> 51.027407 | N10: =AVERAGE(C10:D10) -> 34.494686 | O10: =AVERAGE(E10:L10) -> 55.160587 | P10: Scale Now | R10: D8 | S10: Economic Performance
A11: VI | B11: O'Higgins | C11: 31.870607 | D11: 27.604044 | E11: 20.709534 | F11: 12.34056 | G11: 7.6977449 | H11: 24.840676 | I11: 63.960311 | J11: 55.401254 | K11: 15.779573 | L11: 16.699545 | M11: =AVERAGE(C11:L11) -> 27.690385 | N11: =AVERAGE(C11:D11) -> 29.737326 | O11: =AVERAGE(E11:L11) -> 27.17865 | P11: Prepare First | R11: D9 | S11: Tourism Promotion
A12: VII | B12: Maule | C12: 20.217145 | D12: 37.229514 | E12: 15.325348 | F12: 12.565201 | G12: 16.997188 | H12: 18.186511 | I12: 60.900703 | J12: 49.52087 | K12: 15.602437 | L12: 34.627124 | M12: =AVERAGE(C12:L12) -> 28.117204 | N12: =AVERAGE(C12:D12) -> 28.723329 | O12: =AVERAGE(E12:L12) -> 27.965673 | P12: Prepare First | R12: D10 | S12: Governmental Involvement & Efficiency
A13: VIII | B13: Biobío | C13: 21.060624 | D13: 32.058918 | E13: 25.827107 | F13: 16.647261 | G13: 27.946126 | H13: 19.696254 | I13: 66.454617 | J13: 46.949347 | K13: 31.552845 | L13: 80.268633 | M13: =AVERAGE(C13:L13) -> 36.846173 | N13: =AVERAGE(C13:D13) -> 26.559771 | O13: =AVERAGE(E13:L13) -> 39.417774 | P13: Prepare First
A14: IX | B14: Araucanía | C14: 29.59021 | D14: 55.755648 | E14: 20.514875 | F14: 28.479407 | G14: 27.685449 | H14: 31.024615 | I14: 59.918547 | J14: 35.097898 | K14: 13.081496 | L14: 34.779168 | M14: =AVERAGE(C14:L14) -> 33.592731 | N14: =AVERAGE(C14:D14) -> 42.672929 | O14: =AVERAGE(E14:L14) -> 31.322682 | P14: Prepare First
A15: XIV | B15: Los Ríos | C15: 10.029857 | D15: 37.095409 | E15: 13.450882 | F15: 18.800846 | G15: 12.062514 | H15: 24.201186 | I15: 65.054051 | J15: 49.323312 | K15: 21.844652 | L15: 16.567345 | M15: =AVERAGE(C15:L15) -> 26.843005 | N15: =AVERAGE(C15:D15) -> 23.562633 | O15: =AVERAGE(E15:L15) -> 27.663098 | P15: Prepare First
A16: X | B16: Los Lagos | C16: 19.91888 | D16: 57.620097 | E16: 27.465591 | F16: 34.780082 | G16: 53.150092 | H16: 28.104657 | I16: 64.690324 | J16: 70.101033 | K16: 31.392222 | L16: 55.723977 | M16: =AVERAGE(C16:L16) -> 44.294696 | N16: =AVERAGE(C16:D16) -> 38.769488 | O16: =AVERAGE(E16:L16) -> 45.675997 | P16: Scale Now
A17: XI | B17: Aysén | C17: 6.3100783 | D17: 57.599532 | E17: 35.126914 | F17: 13.726549 | G17: 16.704865 | H17: 35.477878 | I17: 49.139991 | J17: 64.88177 | K17: 38.478971 | L17: 22.463047 | M17: =AVERAGE(C17:L17) -> 33.99096 | N17: =AVERAGE(C17:D17) -> 31.954805 | O17: =AVERAGE(E17:L17) -> 34.499998 | P17: Prepare First
A18: XII | B18: Magallanes y Antártica | C18: 13.39979 | D18: 50.938571 | E18: 44.880707 | F18: 33.284446 | G18: 32.649898 | H18: 43.239919 | I18: 65.922953 | J18: 52.948105 | K18: 47.66839 | L18: 9.9771008 | M18: =AVERAGE(C18:L18) -> 39.490988 | N18: =AVERAGE(C18:D18) -> 32.16918 | O18: =AVERAGE(E18:L18) -> 41.32144 | P18: Scale Now

Sheet Identity_Scoring
A1: Tourism Identity Scoring: Indicator Evidence per Region (0–100)
A2: Each identity score = mean of min–max-normalised DB1/DB2 indicators mapped to that identity (mapping below). Final calls apply documented judgment where indicators are ambiguous.
A3: Code | B3: Region | C3: Nature & Adventure | D3: Culture & Heritage | E3: Wine & Gastronomy | F3: Wellness & Thermal | G3: Astro & Desert | H3: Winter & Mountain | I3: Coastal & Cruise | J3: Community & Indigenous
A4: XV | B4: Arica y Parinacota | C4: 23 | D4: 17.6 | E4: 21.3 | F4: 24.6 | G4: 5.1 | H4: 15.4 | I4: 12 | J4: 50.5
A5: I | B5: Tarapacá | C5: 4.9 | D5: 16.6 | E5: 17.9 | F5: 26.5 | G5: 23.7 | H5: 2.6 | I5: 12.8 | J5: 19.7
A6: II | B6: Antofagasta | C6: 24.4 | D6: 28.8 | E6: 28.2 | F6: 15.4 | G6: 56.6 | H6: 34.8 | I6: 24.7 | J6: 13.1
A7: III | B7: Atacama | C7: 14.3 | D7: 10.2 | E7: 22.7 | F7: 13.1 | G7: 45.8 | H7: 17.9 | I7: 22.6 | J7: 13.2
A8: IV | B8: Coquimbo | C8: 9.9 | D8: 10.1 | E8: 36.9 | F8: 14 | G8: 37.5 | H8: 0 | I8: 51.7 | J8: 40.3
A9: V | B9: Valparaíso | C9: 32.7 | D9: 54.2 | E9: 77.1 | F9: 26.6 | G9: 21.6 | H9: 17.7 | I9: 73.3 | J9: 36.8
A10: RM | B10: Metropolitana | C10: 8 | D10: 59.1 | E10: 14.7 | F10: 18.1 | G10: 14.3 | H10: 48.3 | I10: 0 | J10: 32.3
A11: VI | B11: O'Higgins | C11: 14.2 | D11: 29.9 | E11: 52.9 | F11: 9 | G11: 23.6 | H11: 24.5 | I11: 6.6 | J11: 31.2
A12: VII | B12: Maule | C12: 23.4 | D12: 18.5 | E12: 27.1 | F12: 39.6 | G12: 7.7 | H12: 39.5 | I12: 10.9 | J12: 35
A13: VIII | B13: Biobío | C13: 13 | D13: 22.5 | E13: 3 | F13: 14.5 | G13: 33.3 | H13: 18.7 | I13: 12.9 | J13: 20.2
A14: IX | B14: Araucanía | C14: 59.7 | D14: 17.1 | E14: 14.2 | F14: 100 | G14: 12.5 | H14: 62.5 | I14: 12 | J14: 59.3
A15: XIV | B15: Los Ríos | C15: 21.1 | D15: 7.8 | E15: 16.1 | F15: 61.1 | G15: 8.9 | H15: 14.4 | I15: 14.9 | J15: 20.3
... A18: XII | B18: Magallanes y Antártica | C18: 55.4 | D18: 14.1 | E18: 54.2 | F18: 0 | G18: 4.2 | H18: 61.3 | I18: 34.5 | J18: 19
A20: Code | B20: Region | C20: Tier | D20: Data rank 1 | E20: Score | F20: Data rank 2 | G20: Score | H20: Data rank 3 | I20: Score | J20: Final primary | K20: Final secondary | L20: Changed vs v1 | M20: Rationale | N20: Target traveler
A21: XV | B21: Arica y Parinacota | C21: Wait | D21: Community & Indigenous | E21: 50.5 | F21: Wellness & Thermal | G21: 24.6 | H21: Nature & Adventure | I21: 23 | J21: Community & Indigenous | K21: Culture & Heritage | L21: No | M21: Highest data rank; 25% of population identifies as indigenous and 30 archaeological sites (most in Chile) justify a heritage secondary. | N21: responsible cultural and community-based travelers; culture-led city-break and heritage travelers
A22: I | B22: Tarapacá | C22: Wait | D22: Wellness & Thermal | E22: 26.5 | F22: Astro & Desert | G22: 23.7 | H22: Community & Indigenous | I22: 19.7 | J22: Wellness & Thermal | K22: Astro & Desert | L22: No | M22: Follows data rank (thermal 26.5, astro 23.7); both niches are thin in absolute terms, consistent with the Wait tier. | N22: wellness, thermal and regional leisure travelers; experience-seeking, astronomy and photography travelers
A23: II | B23: Antofagasta | C23: Prepare First | D23: Astro & Desert | E23: 56.6 | F23: Winter & Mountain | G23: 34.8 | H23: Culture & Heritage | I23: 28.8 | J23: Astro & Desert | K23: Culture & Heritage | L23: No | M23: Primary follows data (56.6). Secondary overrides 'Winter & Mountain' (volcano count) in favour of 37 historical sites and 16 museums. | N23: experience-seeking, astronomy and photography travelers; culture-led city-break and heritage travelers
A24: III | B24: Atacama | C24: Prepare First | D24: Astro & Desert | E24: 45.8 | F24: Wine & Gastronomy | G24: 22.7 | H24: Coastal & Cruise | I24: 22.6 | J24: Astro & Desert | K24: Coastal & Cruise | L24: No | M24: Primary follows data (45.8). Coastal (22.6) and wine (22.7) tie; 17 beaches and 10 piers make coastal the credible product. | N24: experience-seeking, astronomy and photography travelers; coastal leisure, cruise and family travelers
A25: IV | B25: Coquimbo | C25: Scale Now | D25: Coastal & Cruise | E25: 51.7 | F25: Community & Indigenous | G25: 40.3 | H25: Astro & Desert | I25: 37.5 | J25: Coastal & Cruise | K25: Astro & Desert | L25: No | M25: Primary follows data (51.7). Secondary overrides 'Community' in favour of astro: 7 observatory-type sites, the most in Chile. | N25: coastal leisure, cruise and family travelers; experience-seeking, astronomy and photography travelers
A26: V | B26: Valparaíso | C26: Scale Now | D26: Wine & Gastronomy | E26: 77.1 | F26: Coastal & Cruise | G26: 73.3 | H26: Culture & Heritage | I26: 54.2 | J26: Coastal & Cruise | K26: Culture & Heritage | L26: No | M26: Wine & Gastronomy ranks first (77) on restaurant density; we keep coastal/cruise (31 cruise calls, 59 beaches) and heritage (161 monuments, 2 WHS) and treat wine as a third pillar. | N26: coastal leisure, cruise and family travelers; culture-led city-break and heritage travelers
A27: RM | B27: Metropolitana | C27: Scale Now | D27: Culture & Heritage | E27: 59.1 | F27: Winter & Mountain | G27: 48.3 | H27: Community & Indigenous | I27: 32.3 | J27: Culture & Heritage | K27: Winter & Mountain | L27: Yes | M27: REVISED: data rank Culture 59 vs Winter 48 (35 museums, 404 monuments). Winter stays secondary: 5 ski resorts, the most in Chile. | N27: culture-led city-break and heritage travelers; winter-sports and mountain-adventure travelers
A28: VI | B28: O'Higgins | C28: Prepare First | D28: Wine & Gastronomy | E28: 52.9 | F28: Community & Indigenous | G28: 31.2 | H28: Culture & Heritage | I28: 29.9 | J28: Wine & Gastronomy | K28: Culture & Heritage | L28: No | M28: Primary follows data (52.9); Community (31.2) and Culture (29.9) tie, heritage chosen for the Sewell/Colchagua museum cluster. | N28: affluent culinary and wine travelers; culture-led city-break and heritage travelers
A29: VII | B29: Maule | C29: Prepare First | D29: Wellness & Thermal | E29: 39.6 | F29: Winter & Mountain | G29: 39.5 | H29: Community & Indigenous | I29: 35 | J29: Wellness & Thermal | K29: Winter & Mountain | L29: No | M29: Follows data rank (39.6 vs 39.5). Wine (27) is under-recorded in DB2 (2 vineyards) and should be validated as a third pillar. | N29: wellness, thermal and regional leisure travelers; winter-sports and mountain-adventure travelers
A30: VIII | B30: Biobío | C30: Prepare First | D30: Astro & Desert | E30: 33.3 | F30: Culture & Heritage | G30: 22.5 | H30: Community & Indigenous | I30: 20.2 | J30: Culture & Heritage | K30: Winter & Mountain | L30: No | M30: Data rank 'Astro & Desert' (33) is an artefact of the paleontology indicator; 20 museums and 23 historical sites support heritage. | N30: culture-led city-break and heritage travelers; winter-sports and mountain-adventure travelers
A31: IX | B31: Araucanía | C31: Prepare First | D31: Wellness & Thermal | E31: 100 | F31: Winter & Mountain | G31: 62.5 | H31: Nature & Adventure | I31: 59.7 | J31: Wellness & Thermal | K31: Winter & Mountain | L31: No | M31: Follows data rank (100 / 62.5); nature (60) and Mapuche community tourism (59) are strong third options. | N31: wellness, thermal and regional leisure travelers; winter-sports and mountain-adventure travelers
A32: XIV | B32: Los Ríos | C32: Prepare First | D32: Wellness & Thermal | E32: 61.1 | F32: Nature & Adventure | G32: 21.1 | H32: Community & Indigenous | I32: 20.3 | J32: Wellness & Thermal | K32: Nature & Adventure | L32: No | M32: Follows data rank (61.1 / 21.1). | N32: wellness, thermal and regional leisure travelers; eco-conscious adventure and longer-stay travelers
... A35: XII | B35: Magallanes y Antártica | C35: Scale Now | D35: Winter & Mountain | E35: 61.3 | F35: Nature & Adventure | G35: 55.4 | H35: Wine & Gastronomy | I35: 54.2 | J35: Nature & Adventure | K35: Coastal & Cruise | L35: Yes | M35: REVISED: 57% protected land (highest) and 284k protected-area visitors; 18 cruise calls (Antarctic gateway). Winter score (61) is inflated by 20 glacier sites; one ski resort. | N35: eco-conscious adventure and longer-stay travelers; expedition-cruise and Antarctic-gateway travelers
A37: Identity | B37: DB1/DB2 indicators used (equal weights within identity)
A38: Nature & Adventure | B38: National protected sites (%); hiking trails; visitors to protected sites; rivers, lakes & waterfalls; natural protected sites L2/L3; biosphere reserves; % forest land; glaciers & winter locations; mountains & volcanoes; preserved sites
A39: Culture & Heritage | B39: World cultural heritage sites; museums; national monuments; historical sites; archaeological sites; cultural centers; theaters; theater plays; galleries; exhibits; artistic events; cultural sites L2/L3; heritage architectural houses; artwork sites; % population attending museums
A40: Wine & Gastronomy | B40: Number of vineyards; valleys; density of restaurants; restaurant employment per 10,000
A41: Wellness & Thermal | B41: Thermal centers (DB2); geysers & thermal centers (DB1); spas
A42: Astro & Desert | B42: Observatories/zoos/aquaria/botanical gardens; deserts & dunes; paleontology sites
A43: Winter & Mountain | B43: Ski resorts; mountains & volcanoes; glaciers & winter locations
A44: Coastal & Cruise | B44: Beaches & beach resorts; piers & seashores; cruise arrivals per year; islands & peninsulas; seashore protected sites
A45: Community & Indigenous | B45: % population associated to an indigenous group; local markets; cultural sites L1 (local); popular architecture sites; cultural events scheduled through the year
A47: Known ambiguity: 'Glaciers and winter vacation locations' mixes a nature asset (glaciers) with a winter-sports asset; it is counted in both identities, which is why Aysén and Magallanes score high on Winter & Mountain although each has a single ski resort. Missing indicator values are median-imputed before normalisation.

Sheet Descriptive_Stats
A1: Descriptive Statistics: Demand Panel (DB3), Dimension Scores and Digital Readiness (DB5)
A2: All cells are live formulas on Tableau_TimeSeries (cleaned DB3), Dimension_Scores and Tableau_DigitalReadiness. Latest 4Q = 2024-Q4 to 2025-Q3.
A3: Period | B3: International arrivals | C3: National arrivals | D3: Total arrivals | E3: Avg occupancy % | F3: Avg daily rate USD | G3: Avg length of stay | H3: Intl vs 2019 (%) | I3: National vs 2019 (%)
A4: 2019 | B4: =SUMIFS(Tableau_TimeSeries!$F:$F,Tableau_TimeSeries!$C:$C,2019) -> 500737 | C4: =SUMIFS(Tableau_TimeSeries!$G:$G,Tableau_TimeSeries!$C:$C,2019) -> 1219152 | D4: =B4+C4 -> 1719889 | E4: =AVERAGEIFS(Tableau_TimeSeries!$I:$I,Tableau_TimeSeries!$C:$C,2019) -> 56.69322 | F4: =AVERAGEIFS(Tableau_TimeSeries!$H:$H,Tableau_TimeSeries!$C:$C,2019) -> 107.80983 | G4: =AVERAGEIFS(Tableau_TimeSeries!$J:$J,Tableau_TimeSeries!$C:$C,2019) -> 2.5753333 | H4: =B4/$B$4*100 -> 100 | I4: =C4/$C$4*100 -> 100
A5: 2020 | B5: =SUMIFS(Tableau_TimeSeries!$F:$F,Tableau_TimeSeries!$C:$C,2020) -> 113608 | C5: =SUMIFS(Tableau_TimeSeries!$G:$G,Tableau_TimeSeries!$C:$C,2020) -> 631158 | D5: =B5+C5 -> 744766 | E5: =AVERAGEIFS(Tableau_TimeSeries!$I:$I,Tableau_TimeSeries!$C:$C,2020) -> 35.744068 | F5: =AVERAGEIFS(Tableau_TimeSeries!$H:$H,Tableau_TimeSeries!$C:$C,2020) -> 88.047797 | G5: =AVERAGEIFS(Tableau_TimeSeries!$J:$J,Tableau_TimeSeries!$C:$C,2020) -> 2.5598333 | H5: =B5/$B$4*100 -> 22.688158 | I5: =C5/$C$4*100 -> 51.770247
A6: 2021 | B6: =SUMIFS(Tableau_TimeSeries!$F:$F,Tableau_TimeSeries!$C:$C,2021) -> 119446 | C6: =SUMIFS(Tableau_TimeSeries!$G:$G,Tableau_TimeSeries!$C:$C,2021) -> 638159 | D6: =B6+C6 -> 757605 | E6: =AVERAGEIFS(Tableau_TimeSeries!$I:$I,Tableau_TimeSeries!$C:$C,2021) -> 35.876271 | F6: =AVERAGEIFS(Tableau_TimeSeries!$H:$H,Tableau_TimeSeries!$C:$C,2021) -> 92.5625 | G6: =AVERAGEIFS(Tableau_TimeSeries!$J:$J,Tableau_TimeSeries!$C:$C,2021) -> 2.6036667 | H6: =B6/$B$4*100 -> 23.854039 | I6: =C6/$C$4*100 -> 52.344498
A7: 2022 | B7: =SUMIFS(Tableau_TimeSeries!$F:$F,Tableau_TimeSeries!$C:$C,2022) -> 469817 | C7: =SUMIFS(Tableau_TimeSeries!$G:$G,Tableau_TimeSeries!$C:$C,2022) -> 1176744 | D7: =B7+C7 -> 1646561 | E7: =AVERAGEIFS(Tableau_TimeSeries!$I:$I,Tableau_TimeSeries!$C:$C,2022) -> 50.349153 | F7: =AVERAGEIFS(Tableau_TimeSeries!$H:$H,Tableau_TimeSeries!$C:$C,2022) -> 114.19117 | G7: =AVERAGEIFS(Tableau_TimeSeries!$J:$J,Tableau_TimeSeries!$C:$C,2022) -> 2.6026667 | H7: =B7/$B$4*100 -> 93.825102 | I7: =C7/$C$4*100 -> 96.521517
A8: 2023 | B8: =SUMIFS(Tableau_TimeSeries!$F:$F,Tableau_TimeSeries!$C:$C,2023) -> 639918 | C8: =SUMIFS(Tableau_TimeSeries!$G:$G,Tableau_TimeSeries!$C:$C,2023) -> 1425773 | D8: =B8+C8 -> 2065691 | E8: =AVERAGEIFS(Tableau_TimeSeries!$I:$I,Tableau_TimeSeries!$C:$C,2023) -> 57.383333 | F8: =AVERAGEIFS(Tableau_TimeSeries!$H:$H,Tableau_TimeSeries!$C:$C,2023) -> 125.34593 | G8: =AVERAGEIFS(Tableau_TimeSeries!$J:$J,Tableau_TimeSeries!$C:$C,2023) -> 2.5738333 | H8: =B8/$B$4*100 -> 127.79523 | I8: =C8/$C$4*100 -> 116.94793
A9: 2024 | B9: =SUMIFS(Tableau_TimeSeries!$F:$F,Tableau_TimeSeries!$C:$C,2024) -> 713076 | C9: =SUMIFS(Tableau_TimeSeries!$G:$G,Tableau_TimeSeries!$C:$C,2024) -> 1489548 | D9: =B9+C9 -> 2202624 | E9: =AVERAGEIFS(Tableau_TimeSeries!$I:$I,Tableau_TimeSeries!$C:$C,2024) -> 57.405 | F9: =AVERAGEIFS(Tableau_TimeSeries!$H:$H,Tableau_TimeSeries!$C:$C,2024) -> 131.73328 | G9: =AVERAGEIFS(Tableau_TimeSeries!$J:$J,Tableau_TimeSeries!$C:$C,2024) -> 2.6031667 | H9: =B9/$B$4*100 -> 142.40529 | I9: =C9/$C$4*100 -> 122.17902
A10: Latest 4Q (2024-Q4–2025-Q3) | B10: =SUMIFS(Tableau_TimeSeries!$F:$F,Tableau_TimeSeries!$C:$C,2024,Tableau_TimeSeries!$D:$D,"Q4")+SUMIFS(Tableau_TimeSeries!$F:$F,Tableau_TimeSeries!$C:$C,2025) -> 733718 | C10: =SUMIFS(Tableau_TimeSeries!$G:$G,Tableau_TimeSeries!$C:$C,2024,Tableau_TimeSeries!$D:$D,"Q4")+SUMIFS(Tableau_TimeSeries!$G:$G,Tableau_TimeSeries!$C:$C,2025) -> 1551568 | D10: =B10+C10 -> 2285286 | E10: =(SUMIFS(Tableau_TimeSeries!$I:$I,Tableau_TimeSeries!$C:$C,2024,Tableau_TimeSeries!$D:$D,"Q4")+SUMIFS(Tableau_TimeSeries!$I:$I,Tableau_TimeSeries!$C:$C,2025))/(COUNTIFS(Tableau_TimeSeries!$I:$I,"<>",Tableau_TimeSeries!$C:$C,2024,Tableau_TimeSeries!$D:$D,"Q4")+COUNTIFS(Tableau_TimeSeries!$I:$I,"<>",Tableau_TimeSeries!$C:$C,2025)) -> 57.262069 | F10: =(SUMIFS(Tableau_TimeSeries!$H:$H,Tableau_TimeSeries!$C:$C,2024,Tableau_TimeSeries!$D:$D,"Q4")+SUMIFS(Tableau_TimeSeries!$H:$H,Tableau_TimeSeries!$C:$C,2025))/(COUNTIFS(Tableau_TimeSeries!$H:$H,"<>",Tableau_TimeSeries!$C:$C,2024,Tableau_TimeSeries!$D:$D,"Q4")+COUNTIFS(Tableau_TimeSeries!$H:$H,"<>",Tableau_TimeSeries!$C:$C,2025)) -> 136.0145 | G10: =(SUMIFS(Tableau_TimeSeries!$J:$J,Tableau_TimeSeries!$C:$C,2024,Tableau_TimeSeries!$D:$D,"Q4")+SUMIFS(Tableau_TimeSeries!$J:$J,Tableau_TimeSeries!$C:$C,2025))/(COUNTIFS(Tableau_TimeSeries!$J:$J,"<>",Tableau_TimeSeries!$C:$C,2024,Tableau_TimeSeries!$D:$D,"Q4")+COUNTIFS(Tableau_TimeSeries!$J:$J,"<>",Tableau_TimeSeries!$C:$C,2025)) -> 2.601 | H10: =B10/$B$4*100 -> 146.52762 | I10: =C10/$C$4*100 -> 127.26617
A11: 2025 covers Q1–Q3 only (27-quarter panel). Occupancy and ADR averages skip missing cells and the invalid Araucanía 2022-Q4 occupancy (104.5%, set to missing).
A13: Code | B13: Region | C13: Tier | D13: Intl arrivals latest 4Q | E13: National arrivals latest 4Q | F13: Avg occupancy % latest 4Q | G13: Avg daily rate USD latest 4Q | H13: Intl arrivals 2019 | I13: Intl recovery % (latest 4Q / 2019) | J13: National recovery % | K13: International share %
A14: XV | B14: Arica y Parinacota | C14: Wait | D14: =SUMIFS(Tableau_TimeSeries!$F:$F,Tableau_TimeSeries!$A:$A,"XV",Tableau_TimeSeries!$C:$C,2024,Tableau_TimeSeries!$D:$D,"Q4")+SUMIFS(Tableau_TimeSeries!$F:$F,Tableau_TimeSeries!$A:$A,"XV",Tableau_TimeSeries!$C:$C,2025) -> 27443 | E14: =SUMIFS(Tableau_TimeSeries!$G:$G,Tableau_TimeSeries!$A:$A,"XV",Tableau_TimeSeries!$C:$C,2024,Tableau_TimeSeries!$D:$D,"Q4")+SUMIFS(Tableau_TimeSeries!$G:$G,Tableau_TimeSeries!$A:$A,"XV",Tableau_TimeSeries!$C:$C,2025) -> 62007 | F14: =(SUMIFS(Tableau_TimeSeries!$I:$I,Tableau_TimeSeries!$A:$A,"XV",Tableau_TimeSeries!$C:$C,2024,Tableau_TimeSeries!$D:$D,"Q4")+SUMIFS(Tableau_TimeSeries!$I:$I,Tableau_TimeSeries!$A:$A,"XV",Tableau_TimeSeries!$C:$C,2025))/(COUNTIFS(Tableau_TimeSeries!$I:$I,"<>",Tableau_TimeSeries!$A:$A,"XV",Tableau_TimeSeries!$C:$C,2024,Tableau_TimeSeries!$D:$D,"Q4")+COUNTIFS(Tableau_TimeSeries!$I:$I,"<>",Tableau_TimeSeries!$A:$A,"XV",Tableau_TimeSeries!$C:$C,2025)) -> 57 | G14: =(SUMIFS(Tableau_TimeSeries!$H:$H,Tableau_TimeSeries!$A:$A,"XV",Tableau_TimeSeries!$C:$C,2024,Tableau_TimeSeries!$D:$D,"Q4")+SUMIFS(Tableau_TimeSeries!$H:$H,Tableau_TimeSeries!$A:$A,"XV",Tableau_TimeSeries!$C:$C,2025))/(COUNTIFS(Tableau_TimeSeries!$H:$H,"<>",Tableau_TimeSeries!$A:$A,"XV",Tableau_TimeSeries!$C:$C,2024,Tableau_TimeSeries!$D:$D,"Q4")+COUNTIFS(Tableau_TimeSeries!$H:$H,"<>",Tableau_TimeSeries!$A:$A,"XV",Tableau_TimeSeries!$C:$C,2025)) -> 120.4725 | H14: =SUMIFS(Tableau_TimeSeries!$F:$F,Tableau_TimeSeries!$A:$A,"XV",Tableau_TimeSeries!$C:$C,2019) -> 19830 | I14: =D14/H14*100 -> 138.39133 | J14: =E14/SUMIFS(Tableau_TimeSeries!$G:$G,Tableau_TimeSeries!$A:$A,"XV",Tableau_TimeSeries!$C:$C,2019)*100 -> 132.66651 | K14: =D14/(D14+E14)*100 -> 30.679709
A15: I | B15: Tarapacá | C15: Wait | D15: =SUMIFS(Tableau_TimeSeries!$F:$F,Tableau_TimeSeries!$A:$A,"I",Tableau_TimeSeries!$C:$C,2024,Tableau_TimeSeries!$D:$D,"Q4")+SUMIFS(Tableau_TimeSeries!$F:$F,Tableau_TimeSeries!$A:$A,"I",Tableau_TimeSeries!$C:$C,2025) -> 28257 | E15: =SUMIFS(Tableau_TimeSeries!$G:$G,Tableau_TimeSeries!$A:$A,"I",Tableau_TimeSeries!$C:$C,2024,Tableau_TimeSeries!$D:$D,"Q4")+SUMIFS(Tableau_TimeSeries!$G:$G,Tableau_TimeSeries!$A:$A,"I",Tableau_TimeSeries!$C:$C,2025) -> 58128 | F15: =(SUMIFS(Tableau_TimeSeries!$I:$I,Tableau_TimeSeries!$A:$A,"I",Tableau_TimeSeries!$C:$C,2024,Tableau_TimeSeries!$D:$D,"Q4")+SUMIFS(Tableau_TimeSeries!$I:$I,Tableau_TimeSeries!$A:$A,"I",Tableau_TimeSeries!$C:$C,2025))/(COUNTIFS(Tableau_TimeSeries!$I:$I,"<>",Tableau_TimeSeries!$A:$A,"I",Tableau_TimeSeries!$C:$C,2024,Tableau_TimeSeries!$D:$D,"Q4")+COUNTIFS(Tableau_TimeSeries!$I:$I,"<>",Tableau_TimeSeries!$A:$A,"I",Tableau_TimeSeries!$C:$C,2025)) -> 57.15 | G15: =(SUMIFS(Tableau_TimeSeries!$H:$H,Tableau_TimeSeries!$A:$A,"I",Tableau_TimeSeries!$C:$C,2024,Tableau_TimeSeries!$D:$D,"Q4")+SUMIFS(Tableau_TimeSeries!$H:$H,Tableau_TimeSeries!$A:$A,"I",Tableau_TimeSeries!$C:$C,2025))/(COUNTIFS(Tableau_TimeSeries!$H:$H,"<>",Tableau_TimeSeries!$A:$A,"I",Tableau_TimeSeries!$C:$C,2024,Tableau_TimeSeries!$D:$D,"Q4")+COUNTIFS(Tableau_TimeSeries!$H:$H,"<>",Tableau_TimeSeries!$A:$A,"I",Tableau_TimeSeries!$C:$C,2025)) -> 117.5975 | H15: =SUMIFS(Tableau_TimeSeries!$F:$F,Tableau_TimeSeries!$A:$A,"I",Tableau_TimeSeries!$C:$C,2019) -> 19089 | I15: =D15/H15*100 -> 148.02766 | J15: =E15/SUMIFS(Tableau_TimeSeries!$G:$G,Tableau_TimeSeries!$A:$A,"I",Tableau_TimeSeries!$C:$C,2019)*100 -> 114.37566 | K15: =D15/(D15+E15)*100 -> 32.71054
A16: II | B16: Antofagasta | C16: Prepare First | D16: =SUMIFS(Tableau_TimeSeries!$F:$F,Tableau_TimeSeries!$A:$A,"II",Tableau_TimeSeries!$C:$C,2024,Tableau_TimeSeries!$D:$D,"Q4")+SUMIFS(Tableau_TimeSeries!$F:$F,Tableau_TimeSeries!$A:$A,"II",Tableau_TimeSeries!$C:$C,2025) -> 42832 | E16: =SUMIFS(Tableau_TimeSeries!$G:$G,Tableau_TimeSeries!$A:$A,"II",Tableau_TimeSeries!$C:$C,2024,Tableau_TimeSeries!$D:$D,"Q4")+SUMIFS(Tableau_TimeSeries!$G:$G,Tableau_TimeSeries!$A:$A,"II",Tableau_TimeSeries!$C:$C,2025) -> 96553 | F16: =(SUMIFS(Tableau_TimeSeries!$I:$I,Tableau_TimeSeries!$A:$A,"II",Tableau_TimeSeries!$C:$C,2024,Tableau_TimeSeries!$D:$D,"Q4")+SUMIFS(Tableau_TimeSeries!$I:$I,Tableau_TimeSeries!$A:$A,"II",Tableau_TimeSeries!$C:$C,2025))/(COUNTIFS(Tableau_TimeSeries!$I:$I,"<>",Tableau_TimeSeries!$A:$A,"II",Tableau_TimeSeries!$C:$C,2024,Tableau_TimeSeries!$D:$D,"Q4")+COUNTIFS(Tableau_TimeSeries!$I:$I,"<>",Tableau_TimeSeries!$A:$A,"II",Tableau_TimeSeries!$C:$C,2025)) -> 54.2 | G16: =(SUMIFS(Tableau_TimeSeries!$H:$H,Tableau_TimeSeries!$A:$A,"II",Tableau_TimeSeries!$C:$C,2024,Tableau_TimeSeries!$D:$D,"Q4")+SUMIFS(Tableau_TimeSeries!$H:$H,Tableau_TimeSeries!$A:$A,"II",Tableau_TimeSeries!$C:$C,2025))/(COUNTIFS(Tableau_TimeSeries!$H:$H,"<>",Tableau_TimeSeries!$A:$A,"II",Tableau_TimeSeries!$C:$C,2024,Tableau_TimeSeries!$D:$D,"Q4")+COUNTIFS(Tableau_TimeSeries!$H:$H,"<>",Tableau_TimeSeries!$A:$A,"II",Tableau_TimeSeries!$C:$C,2025)) -> 121.5225 | H16: =SUMIFS(Tableau_TimeSeries!$F:$F,Tableau_TimeSeries!$A:$A,"II",Tableau_TimeSeries!$C:$C,2019) -> 33755 | I16: =D16/H16*100 -> 126.89083 | J16: =E16/SUMIFS(Tableau_TimeSeries!$G:$G,Tableau_TimeSeries!$A:$A,"II",Tableau_TimeSeries!$C:$C,2019)*100 -> 120.36176 | K16: =D16/(D16+E16)*100 -> 30.729275
A17: III | B17: Atacama | C17: Prepare First | D17: =SUMIFS(Tableau_TimeSeries!$F:$F,Tableau_TimeSeries!$A:$A,"III",Tableau_TimeSeries!$C:$C,2024,Tableau_TimeSeries!$D:$D,"Q4")+SUMIFS(Tableau_TimeSeries!$F:$F,Tableau_TimeSeries!$A:$A,"III",Tableau_TimeSeries!$C:$C,2025) -> 34383 | E17: =SUMIFS(Tableau_TimeSeries!$G:$G,Tableau_TimeSeries!$A:$A,"III",Tableau_TimeSeries!$C:$C,2024,Tableau_TimeSeries!$D:$D,"Q4")+SUMIFS(Tableau_TimeSeries!$G:$G,Tableau_TimeSeries!$A:$A,"III",Tableau_TimeSeries!$C:$C,2025) -> 75620 | F17: =(SUMIFS(Tableau_TimeSeries!$I:$I,Tableau_TimeSeries!$A:$A,"III",Tableau_TimeSeries!$C:$C,2024,Tableau_TimeSeries!$D:$D,"Q4")+SUMIFS(Tableau_TimeSeries!$I:$I,Tableau_TimeSeries!$A:$A,"III",Tableau_TimeSeries!$C:$C,2025))/(COUNTIFS(Tableau_TimeSeries!$I:$I,"<>",Tableau_TimeSeries!$A:$A,"III",Tableau_TimeSeries!$C:$C,2024,Tableau_TimeSeries!$D:$D,"Q4")+COUNTIFS(Tableau_TimeSeries!$I:$I,"<>",Tableau_TimeSeries!$A:$A,"III",Tableau_TimeSeries!$C:$C,2025)) -> 57.35 | G17: =(SUMIFS(Tableau_TimeSeries!$H:$H,Tableau_TimeSeries!$A:$A,"III",Tableau_TimeSeries!$C:$C,2024,Tableau_TimeSeries!$D:$D,"Q4")+SUMIFS(Tableau_TimeSeries!$H:$H,Tableau_TimeSeries!$A:$A,"III",Tableau_TimeSeries!$C:$C,2025))/(COUNTIFS(Tableau_TimeSeries!$H:$H,"<>",Tableau_TimeSeries!$A:$A,"III",Tableau_TimeSeries!$C:$C,2024,Tableau_TimeSeries!$D:$D,"Q4")+COUNTIFS(Tableau_TimeSeries!$H:$H,"<>",Tableau_TimeSeries!$A:$A,"III",Tableau_TimeSeries!$C:$C,2025)) -> 121.285 | H17: =SUMIFS(Tableau_TimeSeries!$F:$F,Tableau_TimeSeries!$A:$A,"III",Tableau_TimeSeries!$C:$C,2019) -> 24877 | I17: =D17/H17*100 -> 138.212 | J17: =E17/SUMIFS(Tableau_TimeSeries!$G:$G,Tableau_TimeSeries!$A:$A,"III",Tableau_TimeSeries!$C:$C,2019)*100 -> 117.87629 | K17: =D17/(D17+E17)*100 -> 31.25642
A18: IV | B18: Coquimbo | C18: Scale Now | D18: =SUMIFS(Tableau_TimeSeries!$F:$F,Tableau_TimeSeries!$A:$A,"IV",Tableau_TimeSeries!$C:$C,2024,Tableau_TimeSeries!$D:$D,"Q4")+SUMIFS(Tableau_TimeSeries!$F:$F,Tableau_TimeSeries!$A:$A,"IV",Tableau_TimeSeries!$C:$C,2025) -> 46864 | E18: =SUMIFS(Tableau_TimeSeries!$G:$G,Tableau_TimeSeries!$A:$A,"IV",Tableau_TimeSeries!$C:$C,2024,Tableau_TimeSeries!$D:$D,"Q4")+SUMIFS(Tableau_TimeSeries!$G:$G,Tableau_TimeSeries!$A:$A,"IV",Tableau_TimeSeries!$C:$C,2025) -> 92537 | F18: =(SUMIFS(Tableau_TimeSeries!$I:$I,Tableau_TimeSeries!$A:$A,"IV",Tableau_TimeSeries!$C:$C,2024,Tableau_TimeSeries!$D:$D,"Q4")+SUMIFS(Tableau_TimeSeries!$I:$I,Tableau_TimeSeries!$A:$A,"IV",Tableau_TimeSeries!$C:$C,2025))/(COUNTIFS(Tableau_TimeSeries!$I:$I,"<>",Tableau_TimeSeries!$A:$A,"IV",Tableau_TimeSeries!$C:$C,2024,Tableau_TimeSeries!$D:$D,"Q4")+COUNTIFS(Tableau_TimeSeries!$I:$I,"<>",Tableau_TimeSeries!$A:$A,"IV",Tableau_TimeSeries!$C:$C,2025)) -> 61.475 | G18: =(SUMIFS(Tableau_TimeSeries!$H:$H,Tableau_TimeSeries!$A:$A,"IV",Tableau_TimeSeries!$C:$C,2024,Tableau_TimeSeries!$D:$D,"Q4")+SUMIFS(Tableau_TimeSeries!$H:$H,Tableau_TimeSeries!$A:$A,"IV",Tableau_TimeSeries!$C:$C,2025))/(COUNTIFS(Tableau_TimeSeries!$H:$H,"<>",Tableau_TimeSeries!$A:$A,"IV",Tableau_TimeSeries!$C:$C,2024,Tableau_TimeSeries!$D:$D,"Q4")+COUNTIFS(Tableau_TimeSeries!$H:$H,"<>",Tableau_TimeSeries!$A:$A,"IV",Tableau_TimeSeries!$C:$C,2025)) -> 132.575 | H18: =SUMIFS(Tableau_TimeSeries!$F:$F,Tableau_TimeSeries!$A:$A,"IV",Tableau_TimeSeries!$C:$C,2019) -> 29596 | I18: =D18/H18*100 -> 158.34572 | J18: =E18/SUMIFS(Tableau_TimeSeries!$G:$G,Tableau_TimeSeries!$A:$A,"IV",Tableau_TimeSeries!$C:$C,2019)*100 -> 125.12778 | K18: =D18/(D18+E18)*100 -> 33.618123
A19: V | B19: Valparaíso | C19: Scale Now | D19: =SUMIFS(Tableau_TimeSeries!$F:$F,Tableau_TimeSeries!$A:$A,"V",Tableau_TimeSeries!$C:$C,2024,Tableau_TimeSeries!$D:$D,"Q4")+SUMIFS(Tableau_TimeSeries!$F:$F,Tableau_TimeSeries!$A:$A,"V",Tableau_TimeSeries!$C:$C,2025) -> 83544 | E19: =SUMIFS(Tableau_TimeSeries!$G:$G,Tableau_TimeSeries!$A:$A,"V",Tableau_TimeSeries!$C:$C,2024,Tableau_TimeSeries!$D:$D,"Q4")+SUMIFS(Tableau_TimeSeries!$G:$G,Tableau_TimeSeries!$A:$A,"V",Tableau_TimeSeries!$C:$C,2025) -> 189639 | F19: =(SUMIFS(Tableau_TimeSeries!$I:$I,Tableau_TimeSeries!$A:$A,"V",Tableau_TimeSeries!$C:$C,2024,Tableau_TimeSeries!$D:$D,"Q4")+SUMIFS(Tableau_TimeSeries!$I:$I,Tableau_TimeSeries!$A:$A,"V",Tableau_TimeSeries!$C:$C,2025))/(COUNTIFS(Tableau_TimeSeries!$I:$I,"<>",Tableau_TimeSeries!$A:$A,"V",Tableau_TimeSeries!$C:$C,2024,Tableau_TimeSeries!$D:$D,"Q4")+COUNTIFS(Tableau_TimeSeries!$I:$I,"<>",Tableau_TimeSeries!$A:$A,"V",Tableau_TimeSeries!$C:$C,2025)) -> 64.325 | G19: =(SUMIFS(Tableau_TimeSeries!$H:$H,Tableau_TimeSeries!$A:$A,"V",Tableau_TimeSeries!$C:$C,2024,Tableau_TimeSeries!$D:$D,"Q4")+SUMIFS(Tableau_TimeSeries!$H:$H,Tableau_TimeSeries!$A:$A,"V",Tableau_TimeSeries!$C:$C,2025))/(COUNTIFS(Tableau_TimeSeries!$H:$H,"<>",Tableau_TimeSeries!$A:$A,"V",Tableau_TimeSeries!$C:$C,2024,Tableau_TimeSeries!$D:$D,"Q4")+COUNTIFS(Tableau_TimeSeries!$H:$H,"<>",Tableau_TimeSeries!$A:$A,"V",Tableau_TimeSeries!$C:$C,2025)) -> 135.7025 | H19: =SUMIFS(Tableau_TimeSeries!$F:$F,Tableau_TimeSeries!$A:$A,"V",Tableau_TimeSeries!$C:$C,2019) -> 64881 | I19: =D19/H19*100 -> 128.76497 | J19: =E19/SUMIFS(Tableau_TimeSeries!$G:$G,Tableau_TimeSeries!$A:$A,"V",Tableau_TimeSeries!$C:$C,2019)*100 -> 122.92031 | K19: =D19/(D19+E19)*100 -> 30.581698
A20: RM | B20: Metropolitana | C20: Scale Now | D20: =SUMIFS(Tableau_TimeSeries!$F:$F,Tableau_TimeSeries!$A:$A,"RM",Tableau_TimeSeries!$C:$C,2024,Tableau_TimeSeries!$D:$D,"Q4")+SUMIFS(Tableau_TimeSeries!$F:$F,Tableau_TimeSeries!$A:$A,"RM",Tableau_TimeSeries!$C:$C,2025) -> 165173 | E20: =SUMIFS(Tableau_TimeSeries!$G:$G,Tableau_TimeSeries!$A:$A,"RM",Tableau_TimeSeries!$C:$C,2024,Tableau_TimeSeries!$D:$D,"Q4")+SUMIFS(Tableau_TimeSeries!$G:$G,Tableau_TimeSeries!$A:$A,"RM",Tableau_TimeSeries!$C:$C,2025) -> 310477 | F20: =(SUMIFS(Tableau_TimeSeries!$I:$I,Tableau_TimeSeries!$A:$A,"RM",Tableau_TimeSeries!$C:$C,2024,Tableau_TimeSeries!$D:$D,"Q4")+SUMIFS(Tableau_TimeSeries!$I:$I,Tableau_TimeSeries!$A:$A,"RM",Tableau_TimeSeries!$C:$C,2025))/(COUNTIFS(Tableau_TimeSeries!$I:$I,"<>",Tableau_TimeSeries!$A:$A,"RM",Tableau_TimeSeries!$C:$C,2024,Tableau_TimeSeries!$D:$D,"Q4")+COUNTIFS(Tableau_TimeSeries!$I:$I,"<>",Tableau_TimeSeries!$A:$A,"RM",Tableau_TimeSeries!$C:$C,2025)) -> 62 | G20: =(SUMIFS(Tableau_TimeSeries!$H:$H,Tableau_TimeSeries!$A:$A,"RM",Tableau_TimeSeries!$C:$C,2024,Tableau_TimeSeries!$D:$D,"Q4")+SUMIFS(Tableau_TimeSeries!$H:$H,Tableau_TimeSeries!$A:$A,"RM",Tableau_TimeSeries!$C:$C,2025))/(COUNTIFS(Tableau_TimeSeries!$H:$H,"<>",Tableau_TimeSeries!$A:$A,"RM",Tableau_TimeSeries!$C:$C,2024,Tableau_TimeSeries!$D:$D,"Q4")+COUNTIFS(Tableau_TimeSeries!$H:$H,"<>",Tableau_TimeSeries!$A:$A,"RM",Tableau_TimeSeries!$C:$C,2025)) -> 177.9475 | H20: =SUMIFS(Tableau_TimeSeries!$F:$F,Tableau_TimeSeries!$A:$A,"RM",Tableau_TimeSeries!$C:$C,2019) -> 94539 | I20: =D20/H20*100 -> 174.71414 | J20: =E20/SUMIFS(Tableau_TimeSeries!$G:$G,Tableau_TimeSeries!$A:$A,"RM",Tableau_TimeSeries!$C:$C,2019)*100 -> 134.59383 | K20: =D20/(D20+E20)*100 -> 34.725744
A21: VI | B21: O'Higgins | C21: Prepare First | D21: =SUMIFS(Tableau_TimeSeries!$F:$F,Tableau_TimeSeries!$A:$A,"VI",Tableau_TimeSeries!$C:$C,2024,Tableau_TimeSeries!$D:$D,"Q4")+SUMIFS(Tableau_TimeSeries!$F:$F,Tableau_TimeSeries!$A:$A,"VI",Tableau_TimeSeries!$C:$C,2025) -> 25232 | E21: =SUMIFS(Tableau_TimeSeries!$G:$G,Tableau_TimeSeries!$A:$A,"VI",Tableau_TimeSeries!$C:$C,2024,Tableau_TimeSeries!$D:$D,"Q4")+SUMIFS(Tableau_TimeSeries!$G:$G,Tableau_TimeSeries!$A:$A,"VI",Tableau_TimeSeries!$C:$C,2025) -> 54933 | F21: =(SUMIFS(Tableau_TimeSeries!$I:$I,Tableau_TimeSeries!$A:$A,"VI",Tableau_TimeSeries!$C:$C,2024,Tableau_TimeSeries!$D:$D,"Q4")+SUMIFS(Tableau_TimeSeries!$I:$I,Tableau_TimeSeries!$A:$A,"VI",Tableau_TimeSeries!$C:$C,2025))/(COUNTIFS(Tableau_TimeSeries!$I:$I,"<>",Tableau_TimeSeries!$A:$A,"VI",Tableau_TimeSeries!$C:$C,2024,Tableau_TimeSeries!$D:$D,"Q4")+COUNTIFS(Tableau_TimeSeries!$I:$I,"<>",Tableau_TimeSeries!$A:$A,"VI",Tableau_TimeSeries!$C:$C,2025)) -> 58.25 | G21: =(SUMIFS(Tableau_TimeSeries!$H:$H,Tableau_TimeSeries!$A:$A,"VI",Tableau_TimeSeries!$C:$C,2024,Tableau_TimeSeries!$D:$D,"Q4")+SUMIFS(Tableau_TimeSeries!$H:$H,Tableau_TimeSeries!$A:$A,"VI",Tableau_TimeSeries!$C:$C,2025))/(COUNTIFS(Tableau_TimeSeries!$H:$H,"<>",Tableau_TimeSeries!$A:$A,"VI",Tableau_TimeSeries!$C:$C,2024,Tableau_TimeSeries!$D:$D,"Q4")+COUNTIFS(Tableau_TimeSeries!$H:$H,"<>",Tableau_TimeSeries!$A:$A,"VI",Tableau_TimeSeries!$C:$C,2025)) -> 105.1225 | H21: =SUMIFS(Tableau_TimeSeries!$F:$F,Tableau_TimeSeries!$A:$A,"VI",Tableau_TimeSeries!$C:$C,2019) -> 20633 | I21: =D21/H21*100 -> 122.28954 | J21: =E21/SUMIFS(Tableau_TimeSeries!$G:$G,Tableau_TimeSeries!$A:$A,"VI",Tableau_TimeSeries!$C:$C,2019)*100 -> 114.1892 | K21: =D21/(D21+E21)*100 -> 31.475083
A22: VII | B22: Maule | C22: Prepare First | D22: =SUMIFS(Tableau_TimeSeries!$F:$F,Tableau_TimeSeries!$A:$A,"VII",Tableau_TimeSeries!$C:$C,2024,Tableau_TimeSeries!$D:$D,"Q4")+SUMIFS(Tableau_TimeSeries!$F:$F,Tableau_TimeSeries!$A:$A,"VII",Tableau_TimeSeries!$C:$C,2025) -> 34396 | E22: =SUMIFS(Tableau_TimeSeries!$G:$G,Tableau_TimeSeries!$A:$A,"VII",Tableau_TimeSeries!$C:$C,2024,Tableau_TimeSeries!$D:$D,"Q4")+SUMIFS(Tableau_TimeSeries!$G:$G,Tableau_TimeSeries!$A:$A,"VII",Tableau_TimeSeries!$C:$C,2025) -> 73670 | F22: =(SUMIFS(Tableau_TimeSeries!$I:$I,Tableau_TimeSeries!$A:$A,"VII",Tableau_TimeSeries!$C:$C,2024,Tableau_TimeSeries!$D:$D,"Q4")+SUMIFS(Tableau_TimeSeries!$I:$I,Tableau_TimeSeries!$A:$A,"VII",Tableau_TimeSeries!$C:$C,2025))/(COUNTIFS(Tableau_TimeSeries!$I:$I,"<>",Tableau_TimeSeries!$A:$A,"VII",Tableau_TimeSeries!$C:$C,2024,Tableau_TimeSeries!$D:$D,"Q4")+COUNTIFS(Tableau_TimeSeries!$I:$I,"<>",Tableau_TimeSeries!$A:$A,"VII",Tableau_TimeSeries!$C:$C,2025)) -> 62.75 | G22: =(SUMIFS(Tableau_TimeSeries!$H:$H,Tableau_TimeSeries!$A:$A,"VII",Tableau_TimeSeries!$C:$C,2024,Tableau_TimeSeries!$D:$D,"Q4")+SUMIFS(Tableau_TimeSeries!$H:$H,Tableau_TimeSeries!$A:$A,"VII",Tableau_TimeSeries!$C:$C,2025))/(COUNTIFS(Tableau_TimeSeries!$H:$H,"<>",Tableau_TimeSeries!$A:$A,"VII",Tableau_TimeSeries!$C:$C,2024,Tableau_TimeSeries!$D:$D,"Q4")+COUNTIFS(Tableau_TimeSeries!$H:$H,"<>",Tableau_TimeSeries!$A:$A,"VII",Tableau_TimeSeries!$C:$C,2025)) -> 159.355 | H22: =SUMIFS(Tableau_TimeSeries!$F:$F,Tableau_TimeSeries!$A:$A,"VII",Tableau_TimeSeries!$C:$C,2019) -> 21817 | I22: =D22/H22*100 -> 157.65687 | J22: =E22/SUMIFS(Tableau_TimeSeries!$G:$G,Tableau_TimeSeries!$A:$A,"VII",Tableau_TimeSeries!$C:$C,2019)*100 -> 133.16102 | K22: =D22/(D22+E22)*100 -> 31.828697
A23: VIII | B23: Biobío | C23: Prepare First | D23: =SUMIFS(Tableau_TimeSeries!$F:$F,Tableau_TimeSeries!$A:$A,"VIII",Tableau_TimeSeries!$C:$C,2024,Tableau_TimeSeries!$D:$D,"Q4")+SUMIFS(Tableau_TimeSeries!$F:$F,Tableau_TimeSeries!$A:$A,"VIII",Tableau_TimeSeries!$C:$C,2025) -> 46785 | E23: =SUMIFS(Tableau_TimeSeries!$G:$G,Tableau_TimeSeries!$A:$A,"VIII",Tableau_TimeSeries!$C:$C,2024,Tableau_TimeSeries!$D:$D,"Q4")+SUMIFS(Tableau_TimeSeries!$G:$G,Tableau_TimeSeries!$A:$A,"VIII",Tableau_TimeSeries!$C:$C,2025) -> 97803 | F23: =(SUMIFS(Tableau_TimeSeries!$I:$I,Tableau_TimeSeries!$A:$A,"VIII",Tableau_TimeSeries!$C:$C,2024,Tableau_TimeSeries!$D:$D,"Q4")+SUMIFS(Tableau_TimeSeries!$I:$I,Tableau_TimeSeries!$A:$A,"VIII",Tableau_TimeSeries!$C:$C,2025))/(COUNTIFS(Tableau_TimeSeries!$I:$I,"<>",Tableau_TimeSeries!$A:$A,"VIII",Tableau_TimeSeries!$C:$C,2024,Tableau_TimeSeries!$D:$D,"Q4")+COUNTIFS(Tableau_TimeSeries!$I:$I,"<>",Tableau_TimeSeries!$A:$A,"VIII",Tableau_TimeSeries!$C:$C,2025)) -> 54.35 | G23: =(SUMIFS(Tableau_TimeSeries!$H:$H,Tableau_TimeSeries!$A:$A,"VIII",Tableau_TimeSeries!$C:$C,2024,Tableau_TimeSeries!$D:$D,"Q4")+SUMIFS(Tableau_TimeSeries!$H:$H,Tableau_TimeSeries!$A:$A,"VIII",Tableau_TimeSeries!$C:$C,2025))/(COUNTIFS(Tableau_TimeSeries!$H:$H,"<>",Tableau_TimeSeries!$A:$A,"VIII",Tableau_TimeSeries!$C:$C,2024,Tableau_TimeSeries!$D:$D,"Q4")+COUNTIFS(Tableau_TimeSeries!$H:$H,"<>",Tableau_TimeSeries!$A:$A,"VIII",Tableau_TimeSeries!$C:$C,2025)) -> 128.78 | H23: =SUMIFS(Tableau_TimeSeries!$F:$F,Tableau_TimeSeries!$A:$A,"VIII",Tableau_TimeSeries!$C:$C,2019) -> 30992 | I23: =D23/H23*100 -> 150.95831 | J23: =E23/SUMIFS(Tableau_TimeSeries!$G:$G,Tableau_TimeSeries!$A:$A,"VIII",Tableau_TimeSeries!$C:$C,2019)*100 -> 127.02843 | K23: =D23/(D23+E23)*100 -> 32.357457
A24: IX | B24: Araucanía | C24: Prepare First | D24: =SUMIFS(Tableau_TimeSeries!$F:$F,Tableau_TimeSeries!$A:$A,"IX",Tableau_TimeSeries!$C:$C,2024,Tableau_TimeSeries!$D:$D,"Q4")+SUMIFS(Tableau_TimeSeries!$F:$F,Tableau_TimeSeries!$A:$A,"IX",Tableau_TimeSeries!$C:$C,2025) -> 52059 | E24: =SUMIFS(Tableau_TimeSeries!$G:$G,Tableau_TimeSeries!$A:$A,"IX",Tableau_TimeSeries!$C:$C,2024,Tableau_TimeSeries!$D:$D,"Q4")+SUMIFS(Tableau_TimeSeries!$G:$G,Tableau_TimeSeries!$A:$A,"IX",Tableau_TimeSeries!$C:$C,2025) -> 111387 | F24: =(SUMIFS(Tableau_TimeSeries!$I:$I,Tableau_TimeSeries!$A:$A,"IX",Tableau_TimeSeries!$C:$C,2024,Tableau_TimeSeries!$D:$D,"Q4")+SUMIFS(Tableau_TimeSeries!$I:$I,Tableau_TimeSeries!$A:$A,"IX",Tableau_TimeSeries!$C:$C,2025))/(COUNTIFS(Tableau_TimeSeries!$I:$I,"<>",Tableau_TimeSeries!$A:$A,"IX",Tableau_TimeSeries!$C:$C,2024,Tableau_TimeSeries!$D:$D,"Q4")+COUNTIFS(Tableau_TimeSeries!$I:$I,"<>",Tableau_TimeSeries!$A:$A,"IX",Tableau_TimeSeries!$C:$C,2025)) -> 49.7 | G24: =(SUMIFS(Tableau_TimeSeries!$H:$H,Tableau_TimeSeries!$A:$A,"IX",Tableau_TimeSeries!$C:$C,2024,Tableau_TimeSeries!$D:$D,"Q4")+SUMIFS(Tableau_TimeSeries!$H:$H,Tableau_TimeSeries!$A:$A,"IX",Tableau_TimeSeries!$C:$C,2025))/(COUNTIFS(Tableau_TimeSeries!$H:$H,"<>",Tableau_TimeSeries!$A:$A,"IX",Tableau_TimeSeries!$C:$C,2024,Tableau_TimeSeries!$D:$D,"Q4")+COUNTIFS(Tableau_TimeSeries!$H:$H,"<>",Tableau_TimeSeries!$A:$A,"IX",Tableau_TimeSeries!$C:$C,2025)) -> 109.0175 | H24: =SUMIFS(Tableau_TimeSeries!$F:$F,Tableau_TimeSeries!$A:$A,"IX",Tableau_TimeSeries!$C:$C,2019) -> 36346 | I24: =D24/H24*100 -> 143.23172 | J24: =E24/SUMIFS(Tableau_TimeSeries!$G:$G,Tableau_TimeSeries!$A:$A,"IX",Tableau_TimeSeries!$C:$C,2019)*100 -> 126.45399 | K24: =D24/(D24+E24)*100 -> 31.850887
A25: XIV | B25: Los Ríos | C25: Prepare First | D25: =SUMIFS(Tableau_TimeSeries!$F:$F,Tableau_TimeSeries!$A:$A,"XIV",Tableau_TimeSeries!$C:$C,2024,Tableau_TimeSeries!$D:$D,"Q4")+SUMIFS(Tableau_TimeSeries!$F:$F,Tableau_TimeSeries!$A:$A,"XIV",Tableau_TimeSeries!$C:$C,2025) -> 29814 | E25: =SUMIFS(Tableau_TimeSeries!$G:$G,Tableau_TimeSeries!$A:$A,"XIV",Tableau_TimeSeries!$C:$C,2024,Tableau_TimeSeries!$D:$D,"Q4")+SUMIFS(Tableau_TimeSeries!$G:$G,Tableau_TimeSeries!$A:$A,"XIV",Tableau_TimeSeries!$C:$C,2025) -> 69560 | F25: =(SUMIFS(Tableau_TimeSeries!$I:$I,Tableau_TimeSeries!$A:$A,"XIV",Tableau_TimeSeries!$C:$C,2024,Tableau_TimeSeries!$D:$D,"Q4")+SUMIFS(Tableau_TimeSeries!$I:$I,Tableau_TimeSeries!$A:$A,"XIV",Tableau_TimeSeries!$C:$C,2025))/(COUNTIFS(Tableau_TimeSeries!$I:$I,"<>",Tableau_TimeSeries!$A:$A,"XIV",Tableau_TimeSeries!$C:$C,2024,Tableau_TimeSeries!$D:$D,"Q4")+COUNTIFS(Tableau_TimeSeries!$I:$I,"<>",Tableau_TimeSeries!$A:$A,"XIV",Tableau_TimeSeries!$C:$C,2025)) -> 53.775 | G25: =(SUMIFS(Tableau_TimeSeries!$H:$H,Tableau_TimeSeries!$A:$A,"XIV",Tableau_TimeSeries!$C:$C,2024,Tableau_TimeSeries!$D:$D,"Q4")+SUMIFS(Tableau_TimeSeries!$H:$H,Tableau_TimeSeries!$A:$A,"XIV",Tableau_TimeSeries!$C:$C,2025))/(COUNTIFS(Tableau_TimeSeries!$H:$H,"<>",Tableau_TimeSeries!$A:$A,"XIV",Tableau_TimeSeries!$C:$C,2024,Tableau_TimeSeries!$D:$D,"Q4")+COUNTIFS(Tableau_TimeSeries!$H:$H,"<>",Tableau_TimeSeries!$A:$A,"XIV",Tableau_TimeSeries!$C:$C,2025)) -> 113.37 | H25: =SUMIFS(Tableau_TimeSeries!$F:$F,Tableau_TimeSeries!$A:$A,"XIV",Tableau_TimeSeries!$C:$C,2019) -> 22399 | I25: =D25/H25*100 -> 133.10416 | J25: =E25/SUMIFS(Tableau_TimeSeries!$G:$G,Tableau_TimeSeries!$A:$A,"XIV",Tableau_TimeSeries!$C:$C,2019)*100 -> 121.21001 | K25: =D25/(D25+E25)*100 -> 30.001811
A26: X | B26: Los Lagos | C26: Scale Now | D26: =SUMIFS(Tableau_TimeSeries!$F:$F,Tableau_TimeSeries!$A:$A,"X",Tableau_TimeSeries!$C:$C,2024,Tableau_TimeSeries!$D:$D,"Q4")+SUMIFS(Tableau_TimeSeries!$F:$F,Tableau_TimeSeries!$A:$A,"X",Tableau_TimeSeries!$C:$C,2025) -> 72505 | E26: =SUMIFS(Tableau_TimeSeries!$G:$G,Tableau_TimeSeries!$A:$A,"X",Tableau_TimeSeries!$C:$C,2024,Tableau_TimeSeries!$D:$D,"Q4")+SUMIFS(Tableau_TimeSeries!$G:$G,Tableau_TimeSeries!$A:$A,"X",Tableau_TimeSeries!$C:$C,2025) -> 159844 | F26: =(SUMIFS(Tableau_TimeSeries!$I:$I,Tableau_TimeSeries!$A:$A,"X",Tableau_TimeSeries!$C:$C,2024,Tableau_TimeSeries!$D:$D,"Q4")+SUMIFS(Tableau_TimeSeries!$I:$I,Tableau_TimeSeries!$A:$A,"X",Tableau_TimeSeries!$C:$C,2025))/(COUNTIFS(Tableau_TimeSeries!$I:$I,"<>",Tableau_TimeSeries!$A:$A,"X",Tableau_TimeSeries!$C:$C,2024,Tableau_TimeSeries!$D:$D,"Q4")+COUNTIFS(Tableau_TimeSeries!$I:$I,"<>",Tableau_TimeSeries!$A:$A,"X",Tableau_TimeSeries!$C:$C,2025)) -> 53.425 | G26: =(SUMIFS(Tableau_TimeSeries!$H:$H,Tableau_TimeSeries!$A:$A,"X",Tableau_TimeSeries!$C:$C,2024,Tableau_TimeSeries!$D:$D,"Q4")+SUMIFS(Tableau_TimeSeries!$H:$H,Tableau_TimeSeries!$A:$A,"X",Tableau_TimeSeries!$C:$C,2025))/(COUNTIFS(Tableau_TimeSeries!$H:$H,"<>",Tableau_TimeSeries!$A:$A,"X",Tableau_TimeSeries!$C:$C,2024,Tableau_TimeSeries!$D:$D,"Q4")+COUNTIFS(Tableau_TimeSeries!$H:$H,"<>",Tableau_TimeSeries!$A:$A,"X",Tableau_TimeSeries!$C:$C,2025)) -> 132.5525 | H26: =SUMIFS(Tableau_TimeSeries!$F:$F,Tableau_TimeSeries!$A:$A,"X",Tableau_TimeSeries!$C:$C,2019) -> 48256 | I26: =D26/H26*100 -> 150.25075 | J26: =E26/SUMIFS(Tableau_TimeSeries!$G:$G,Tableau_TimeSeries!$A:$A,"X",Tableau_TimeSeries!$C:$C,2019)*100 -> 141.30606 | K26: =D26/(D26+E26)*100 -> 31.205213
A27: XI | B27: Aysén | C27: Prepare First | D27: =SUMIFS(Tableau_TimeSeries!$F:$F,Tableau_TimeSeries!$A:$A,"XI",Tableau_TimeSeries!$C:$C,2024,Tableau_TimeSeries!$D:$D,"Q4")+SUMIFS(Tableau_TimeSeries!$F:$F,Tableau_TimeSeries!$A:$A,"XI",Tableau_TimeSeries!$C:$C,2025) -> 12922 | E27: =SUMIFS(Tableau_TimeSeries!$G:$G,Tableau_TimeSeries!$A:$A,"XI",Tableau_TimeSeries!$C:$C,2024,Tableau_TimeSeries!$D:$D,"Q4")+SUMIFS(Tableau_TimeSeries!$G:$G,Tableau_TimeSeries!$A:$A,"XI",Tableau_TimeSeries!$C:$C,2025) -> 30348 | F27: =(SUMIFS(Tableau_TimeSeries!$I:$I,Tableau_TimeSeries!$A:$A,"XI",Tableau_TimeSeries!$C:$C,2024,Tableau_TimeSeries!$D:$D,"Q4")+SUMIFS(Tableau_TimeSeries!$I:$I,Tableau_TimeSeries!$A:$A,"XI",Tableau_TimeSeries!$C:$C,2025))/(COUNTIFS(Tableau_TimeSeries!$I:$I,"<>",Tableau_TimeSeries!$A:$A,"XI",Tableau_TimeSeries!$C:$C,2024,Tableau_TimeSeries!$D:$D,"Q4")+COUNTIFS(Tableau_TimeSeries!$I:$I,"<>",Tableau_TimeSeries!$A:$A,"XI",Tableau_TimeSeries!$C:$C,2025)) -> 54.933333 | G27: =(SUMIFS(Tableau_TimeSeries!$H:$H,Tableau_TimeSeries!$A:$A,"XI",Tableau_TimeSeries!$C:$C,2024,Tableau_TimeSeries!$D:$D,"Q4")+SUMIFS(Tableau_TimeSeries!$H:$H,Tableau_TimeSeries!$A:$A,"XI",Tableau_TimeSeries!$C:$C,2025))/(COUNTIFS(Tableau_TimeSeries!$H:$H,"<>",Tableau_TimeSeries!$A:$A,"XI",Tableau_TimeSeries!$C:$C,2024,Tableau_TimeSeries!$D:$D,"Q4")+COUNTIFS(Tableau_TimeSeries!$H:$H,"<>",Tableau_TimeSeries!$A:$A,"XI",Tableau_TimeSeries!$C:$C,2025)) -> 166.95 | H27: =SUMIFS(Tableau_TimeSeries!$F:$F,Tableau_TimeSeries!$A:$A,"XI",Tableau_TimeSeries!$C:$C,2019) -> 10472 | I27: =D27/H27*100 -> 123.39572 | J27: =E27/SUMIFS(Tableau_TimeSeries!$G:$G,Tableau_TimeSeries!$A:$A,"XI",Tableau_TimeSeries!$C:$C,2019)*100 -> 120.61044 | K27: =D27/(D27+E27)*100 -> 29.863647
A28: XII | B28: Magallanes y Antártica | C28: Scale Now | D28: =SUMIFS(Tableau_TimeSeries!$F:$F,Tableau_TimeSeries!$A:$A,"XII",Tableau_TimeSeries!$C:$C,2024,Tableau_TimeSeries!$D:$D,"Q4")+SUMIFS(Tableau_TimeSeries!$F:$F,Tableau_TimeSeries!$A:$A,"XII",Tableau_TimeSeries!$C:$C,2025) -> 31509 | E28: =SUMIFS(Tableau_TimeSeries!$G:$G,Tableau_TimeSeries!$A:$A,"XII",Tableau_TimeSeries!$C:$C,2024,Tableau_TimeSeries!$D:$D,"Q4")+SUMIFS(Tableau_TimeSeries!$G:$G,Tableau_TimeSeries!$A:$A,"XII",Tableau_TimeSeries!$C:$C,2025) -> 69062 | F28: =(SUMIFS(Tableau_TimeSeries!$I:$I,Tableau_TimeSeries!$A:$A,"XII",Tableau_TimeSeries!$C:$C,2024,Tableau_TimeSeries!$D:$D,"Q4")+SUMIFS(Tableau_TimeSeries!$I:$I,Tableau_TimeSeries!$A:$A,"XII",Tableau_TimeSeries!$C:$C,2025))/(COUNTIFS(Tableau_TimeSeries!$I:$I,"<>",Tableau_TimeSeries!$A:$A,"XII",Tableau_TimeSeries!$C:$C,2024,Tableau_TimeSeries!$D:$D,"Q4")+COUNTIFS(Tableau_TimeSeries!$I:$I,"<>",Tableau_TimeSeries!$A:$A,"XII",Tableau_TimeSeries!$C:$C,2025)) -> 55.775 | G28: =(SUMIFS(Tableau_TimeSeries!$H:$H,Tableau_TimeSeries!$A:$A,"XII",Tableau_TimeSeries!$C:$C,2024,Tableau_TimeSeries!$D:$D,"Q4")+SUMIFS(Tableau_TimeSeries!$H:$H,Tableau_TimeSeries!$A:$A,"XII",Tableau_TimeSeries!$C:$C,2025))/(COUNTIFS(Tableau_TimeSeries!$H:$H,"<>",Tableau_TimeSeries!$A:$A,"XII",Tableau_TimeSeries!$C:$C,2024,Tableau_TimeSeries!$D:$D,"Q4")+COUNTIFS(Tableau_TimeSeries!$H:$H,"<>",Tableau_TimeSeries!$A:$A,"XII",Tableau_TimeSeries!$C:$C,2025)) -> 197.9675 | H28: =SUMIFS(Tableau_TimeSeries!$F:$F,Tableau_TimeSeries!$A:$A,"XII",Tableau_TimeSeries!$C:$C,2019) -> 23255 | I28: =D28/H28*100 -> 135.49344 | J28: =E28/SUMIFS(Tableau_TimeSeries!$G:$G,Tableau_TimeSeries!$A:$A,"XII",Tableau_TimeSeries!$C:$C,2019)*100 -> 127.57837 | K28: =D28/(D28+E28)*100 -> 31.330105
A30: Dimension | B30: Mean | C30: Std dev | D30: Min | E30: Max | F30: Coefficient of variation | G30: Top region | H30: Bottom region
A31: D1 Cultural Heritage & Events | B31: =AVERAGE(Dimension_Scores!$C$4:$C$18) -> 22.932225 | C31: =STDEV(Dimension_Scores!$C$4:$C$18) -> 13.268901 | D31: =MIN(Dimension_Scores!$C$4:$C$18) -> 6.3100783 | E31: =MAX(Dimension_Scores!$C$4:$C$18) -> 52.04743 | F31: =C31/B31 -> 0.57861377 | G31: =INDEX(Dimension_Scores!$B$4:$B$18,MATCH(MAX(Dimension_Scores!$C$4:$C$18),Dimension_Scores!$C$4:$C$18,0)) -> Metropolitana | H31: =INDEX(Dimension_Scores!$B$4:$B$18,MATCH(MIN(Dimension_Scores!$C$4:$C$18),Dimension_Scores!$C$4:$C$18,0)) -> Aysén
A32: D2 Natural Resources & Sustainability | B32: =AVERAGE(Dimension_Scores!$D$4:$D$18) -> 39.526132 | C32: =STDEV(Dimension_Scores!$D$4:$D$18) -> 11.902039 | D32: =MIN(Dimension_Scores!$D$4:$D$18) -> 16.941943 | E32: =MAX(Dimension_Scores!$D$4:$D$18) -> 57.620097 | F32: =C32/B32 -> 0.30111823 | G32: =INDEX(Dimension_Scores!$B$4:$B$18,MATCH(MAX(Dimension_Scores!$D$4:$D$18),Dimension_Scores!$D$4:$D$18,0)) -> Los Lagos | H32: =INDEX(Dimension_Scores!$B$4:$B$18,MATCH(MIN(Dimension_Scores!$D$4:$D$18),Dimension_Scores!$D$4:$D$18,0)) -> Metropolitana
A33: D3 Human Resources & Workforce | B33: =AVERAGE(Dimension_Scores!$E$4:$E$18) -> 29.209052 | C33: =STDEV(Dimension_Scores!$E$4:$E$18) -> 12.111952 | D33: =MIN(Dimension_Scores!$E$4:$E$18) -> 13.450882 | E33: =MAX(Dimension_Scores!$E$4:$E$18) -> 61.707192 | F33: =C33/B33 -> 0.41466433 | G33: =INDEX(Dimension_Scores!$B$4:$B$18,MATCH(MAX(Dimension_Scores!$E$4:$E$18),Dimension_Scores!$E$4:$E$18,0)) -> Metropolitana | H33: =INDEX(Dimension_Scores!$B$4:$B$18,MATCH(MIN(Dimension_Scores!$E$4:$E$18),Dimension_Scores!$E$4:$E$18,0)) -> Los Ríos
